[21/Dec/2023 23:24:30] INFO [etienda.api:134] Received GET request for products with pagination: desde=0, hasta=10
[21/Dec/2023 23:25:29] INFO [etienda.api:162] Received GET request for product with ID: 65845ea4fc125fb85d27f085
[21/Dec/2023 23:25:43] INFO [etienda.api:162] Received GET request for product with ID: 65845eabfc125fb85d27f086
[21/Dec/2023 23:27:04] INFO [etienda.api:75] Received PUT request for product with ID: 65845eaefc125fb85d27f08a
[21/Dec/2023 23:27:04] INFO [etienda.api:100] Product with ID 65845eaefc125fb85d27f08a successfully updated
[21/Dec/2023 23:27:04] ERROR [django:119] "PUT - mod_product /etienda/api/productos/rate/65845eaefc125fb85d27f08a" ([ErrorWrapper(exc=ValidationError(model='Rate', errors=[{'loc': ('rate',), 'msg': 'field required', 'type': 'value_error.missing'}, {'loc': ('count',), 'msg': 'field required', 'type': 'value_error.missing'}]), loc=('response',))], <class 'abc.NinjaResponseSchema'>)
[21/Dec/2023 23:27:04] ERROR [django:119] "PUT - mod_product /etienda/api/productos/rate/65845eaefc125fb85d27f08a" ([ErrorWrapper(exc=ValidationError(model='Rate', errors=[{'loc': ('rate',), 'msg': 'field required', 'type': 'value_error.missing'}, {'loc': ('count',), 'msg': 'field required', 'type': 'value_error.missing'}]), loc=('response',))], <class 'abc.NinjaResponseSchema'>)
[21/Dec/2023 23:27:04] ERROR [django:106] 2 validation errors for NinjaResponseSchema
response -> rate
  field required (type=value_error.missing)
response -> count
  field required (type=value_error.missing)
Traceback (most recent call last):
  File "/usr/local/lib/python3.11/site-packages/ninja_extra/operation.py", line 193, in run
    _processed_results = self._result_to_response(
                         ^^^^^^^^^^^^^^^^^^^^^^^^^
  File "/usr/local/lib/python3.11/site-packages/ninja/operation.py", line 202, in _result_to_response
    result = response_model.from_orm(resp_object).dict(
             ^^^^^^^^^^^^^^^^^^^^^^^^^^^^^^^^^^^^
  File "/usr/local/lib/python3.11/site-packages/ninja/schema.py", line 164, in from_orm
    return super().from_orm(obj)
           ^^^^^^^^^^^^^^^^^^^^^
  File "pydantic/main.py", line 579, in pydantic.main.BaseModel.from_orm
pydantic.error_wrappers.ValidationError: 2 validation errors for NinjaResponseSchema
response -> rate
  field required (type=value_error.missing)
response -> count
  field required (type=value_error.missing)
[21/Dec/2023 23:27:04] ERROR [django:106] 2 validation errors for NinjaResponseSchema
response -> rate
  field required (type=value_error.missing)
response -> count
  field required (type=value_error.missing)
Traceback (most recent call last):
  File "/usr/local/lib/python3.11/site-packages/ninja_extra/operation.py", line 193, in run
    _processed_results = self._result_to_response(
                         ^^^^^^^^^^^^^^^^^^^^^^^^^
  File "/usr/local/lib/python3.11/site-packages/ninja/operation.py", line 202, in _result_to_response
    result = response_model.from_orm(resp_object).dict(
             ^^^^^^^^^^^^^^^^^^^^^^^^^^^^^^^^^^^^
  File "/usr/local/lib/python3.11/site-packages/ninja/schema.py", line 164, in from_orm
    return super().from_orm(obj)
           ^^^^^^^^^^^^^^^^^^^^^
  File "pydantic/main.py", line 579, in pydantic.main.BaseModel.from_orm
pydantic.error_wrappers.ValidationError: 2 validation errors for NinjaResponseSchema
response -> rate
  field required (type=value_error.missing)
response -> count
  field required (type=value_error.missing)
[21/Dec/2023 23:27:04] ERROR [django.request:241] Internal Server Error: /etienda/api/productos/rate/65845eaefc125fb85d27f08a
[21/Dec/2023 23:27:04] ERROR [django.request:241] Internal Server Error: /etienda/api/productos/rate/65845eaefc125fb85d27f08a
[21/Dec/2023 23:27:04] ERROR [django.server:212] "PUT /etienda/api/productos/rate/65845eaefc125fb85d27f08a HTTP/1.1" 500 872
[21/Dec/2023 23:27:04] ERROR [django.server:212] "PUT /etienda/api/productos/rate/65845eaefc125fb85d27f08a HTTP/1.1" 500 872
[21/Dec/2023 23:27:05] INFO [etienda.api:75] Received PUT request for product with ID: 65845eaefc125fb85d27f08a
[21/Dec/2023 23:27:05] INFO [etienda.api:100] Product with ID 65845eaefc125fb85d27f08a successfully updated
[21/Dec/2023 23:27:05] ERROR [django:119] "PUT - mod_product /etienda/api/productos/rate/65845eaefc125fb85d27f08a" ([ErrorWrapper(exc=ValidationError(model='Rate', errors=[{'loc': ('rate',), 'msg': 'field required', 'type': 'value_error.missing'}, {'loc': ('count',), 'msg': 'field required', 'type': 'value_error.missing'}]), loc=('response',))], <class 'abc.NinjaResponseSchema'>)
[21/Dec/2023 23:27:05] ERROR [django:119] "PUT - mod_product /etienda/api/productos/rate/65845eaefc125fb85d27f08a" ([ErrorWrapper(exc=ValidationError(model='Rate', errors=[{'loc': ('rate',), 'msg': 'field required', 'type': 'value_error.missing'}, {'loc': ('count',), 'msg': 'field required', 'type': 'value_error.missing'}]), loc=('response',))], <class 'abc.NinjaResponseSchema'>)
[21/Dec/2023 23:27:05] ERROR [django:106] 2 validation errors for NinjaResponseSchema
response -> rate
  field required (type=value_error.missing)
response -> count
  field required (type=value_error.missing)
Traceback (most recent call last):
  File "/usr/local/lib/python3.11/site-packages/ninja_extra/operation.py", line 193, in run
    _processed_results = self._result_to_response(
                         ^^^^^^^^^^^^^^^^^^^^^^^^^
  File "/usr/local/lib/python3.11/site-packages/ninja/operation.py", line 202, in _result_to_response
    result = response_model.from_orm(resp_object).dict(
             ^^^^^^^^^^^^^^^^^^^^^^^^^^^^^^^^^^^^
  File "/usr/local/lib/python3.11/site-packages/ninja/schema.py", line 164, in from_orm
    return super().from_orm(obj)
           ^^^^^^^^^^^^^^^^^^^^^
  File "pydantic/main.py", line 579, in pydantic.main.BaseModel.from_orm
pydantic.error_wrappers.ValidationError: 2 validation errors for NinjaResponseSchema
response -> rate
  field required (type=value_error.missing)
response -> count
  field required (type=value_error.missing)
[21/Dec/2023 23:27:05] ERROR [django:106] 2 validation errors for NinjaResponseSchema
response -> rate
  field required (type=value_error.missing)
response -> count
  field required (type=value_error.missing)
Traceback (most recent call last):
  File "/usr/local/lib/python3.11/site-packages/ninja_extra/operation.py", line 193, in run
    _processed_results = self._result_to_response(
                         ^^^^^^^^^^^^^^^^^^^^^^^^^
  File "/usr/local/lib/python3.11/site-packages/ninja/operation.py", line 202, in _result_to_response
    result = response_model.from_orm(resp_object).dict(
             ^^^^^^^^^^^^^^^^^^^^^^^^^^^^^^^^^^^^
  File "/usr/local/lib/python3.11/site-packages/ninja/schema.py", line 164, in from_orm
    return super().from_orm(obj)
           ^^^^^^^^^^^^^^^^^^^^^
  File "pydantic/main.py", line 579, in pydantic.main.BaseModel.from_orm
pydantic.error_wrappers.ValidationError: 2 validation errors for NinjaResponseSchema
response -> rate
  field required (type=value_error.missing)
response -> count
  field required (type=value_error.missing)
[21/Dec/2023 23:27:05] ERROR [django.request:241] Internal Server Error: /etienda/api/productos/rate/65845eaefc125fb85d27f08a
[21/Dec/2023 23:27:05] ERROR [django.request:241] Internal Server Error: /etienda/api/productos/rate/65845eaefc125fb85d27f08a
[21/Dec/2023 23:27:05] ERROR [django.server:212] "PUT /etienda/api/productos/rate/65845eaefc125fb85d27f08a HTTP/1.1" 500 872
[21/Dec/2023 23:27:05] ERROR [django.server:212] "PUT /etienda/api/productos/rate/65845eaefc125fb85d27f08a HTTP/1.1" 500 872
[21/Dec/2023 23:27:44] INFO [etienda.api:75] Received PUT request for product with ID: 65845eaefc125fb85d27f089
[21/Dec/2023 23:27:44] INFO [etienda.api:100] Product with ID 65845eaefc125fb85d27f089 successfully updated
[21/Dec/2023 23:27:44] ERROR [django:119] "PUT - mod_product /etienda/api/productos/rate/65845eaefc125fb85d27f089" ([ErrorWrapper(exc=ValidationError(model='Rate', errors=[{'loc': ('rate',), 'msg': 'field required', 'type': 'value_error.missing'}, {'loc': ('count',), 'msg': 'field required', 'type': 'value_error.missing'}]), loc=('response',))], <class 'abc.NinjaResponseSchema'>)
[21/Dec/2023 23:27:44] ERROR [django:119] "PUT - mod_product /etienda/api/productos/rate/65845eaefc125fb85d27f089" ([ErrorWrapper(exc=ValidationError(model='Rate', errors=[{'loc': ('rate',), 'msg': 'field required', 'type': 'value_error.missing'}, {'loc': ('count',), 'msg': 'field required', 'type': 'value_error.missing'}]), loc=('response',))], <class 'abc.NinjaResponseSchema'>)
[21/Dec/2023 23:27:44] ERROR [django:106] 2 validation errors for NinjaResponseSchema
response -> rate
  field required (type=value_error.missing)
response -> count
  field required (type=value_error.missing)
Traceback (most recent call last):
  File "/usr/local/lib/python3.11/site-packages/ninja_extra/operation.py", line 193, in run
    _processed_results = self._result_to_response(
                         ^^^^^^^^^^^^^^^^^^^^^^^^^
  File "/usr/local/lib/python3.11/site-packages/ninja/operation.py", line 202, in _result_to_response
    result = response_model.from_orm(resp_object).dict(
             ^^^^^^^^^^^^^^^^^^^^^^^^^^^^^^^^^^^^
  File "/usr/local/lib/python3.11/site-packages/ninja/schema.py", line 164, in from_orm
    return super().from_orm(obj)
           ^^^^^^^^^^^^^^^^^^^^^
  File "pydantic/main.py", line 579, in pydantic.main.BaseModel.from_orm
pydantic.error_wrappers.ValidationError: 2 validation errors for NinjaResponseSchema
response -> rate
  field required (type=value_error.missing)
response -> count
  field required (type=value_error.missing)
[21/Dec/2023 23:27:44] ERROR [django:106] 2 validation errors for NinjaResponseSchema
response -> rate
  field required (type=value_error.missing)
response -> count
  field required (type=value_error.missing)
Traceback (most recent call last):
  File "/usr/local/lib/python3.11/site-packages/ninja_extra/operation.py", line 193, in run
    _processed_results = self._result_to_response(
                         ^^^^^^^^^^^^^^^^^^^^^^^^^
  File "/usr/local/lib/python3.11/site-packages/ninja/operation.py", line 202, in _result_to_response
    result = response_model.from_orm(resp_object).dict(
             ^^^^^^^^^^^^^^^^^^^^^^^^^^^^^^^^^^^^
  File "/usr/local/lib/python3.11/site-packages/ninja/schema.py", line 164, in from_orm
    return super().from_orm(obj)
           ^^^^^^^^^^^^^^^^^^^^^
  File "pydantic/main.py", line 579, in pydantic.main.BaseModel.from_orm
pydantic.error_wrappers.ValidationError: 2 validation errors for NinjaResponseSchema
response -> rate
  field required (type=value_error.missing)
response -> count
  field required (type=value_error.missing)
[21/Dec/2023 23:27:44] ERROR [django.request:241] Internal Server Error: /etienda/api/productos/rate/65845eaefc125fb85d27f089
[21/Dec/2023 23:27:44] ERROR [django.request:241] Internal Server Error: /etienda/api/productos/rate/65845eaefc125fb85d27f089
[21/Dec/2023 23:27:44] ERROR [django.server:212] "PUT /etienda/api/productos/rate/65845eaefc125fb85d27f089 HTTP/1.1" 500 872
[21/Dec/2023 23:27:44] ERROR [django.server:212] "PUT /etienda/api/productos/rate/65845eaefc125fb85d27f089 HTTP/1.1" 500 872
